INFO 2020-04-18 13:17:54,357 autoreload 17084 19904 Watching for file changes with StatReloader
INFO 2020-04-18 13:18:23,187 views 17084 11176 >>>>>>>>>>>>>> Something Debug wrong!
INFO 2020-04-18 13:18:23,192 basehttp 17084 11176 "GET /addUser HTTP/1.1" 200 26
WARNING 2020-04-18 13:18:24,217 views 17084 5336 Something warning wrong!
INFO 2020-04-18 13:18:24,218 basehttp 17084 5336 "GET /addSomething HTTP/1.1" 200 31
INFO 2020-04-18 13:18:25,235 views 17084 22124 Something info2 wrong!
INFO 2020-04-18 13:18:25,236 basehttp 17084 22124 "GET /addNew/31 HTTP/1.1" 200 54
ERROR 2020-04-18 13:18:26,396 log 17084 19660 Internal Server Error: /addNewError/58
Traceback (most recent call last):
  File "C:\Users\swsh\AppData\Local\Continuum\anaconda3\envs\py36\lib\site-packages\django\core\handlers\exception.py", line 34, in inner
    response = get_response(request)
  File "C:\Users\swsh\AppData\Local\Continuum\anaconda3\envs\py36\lib\site-packages\django\core\handlers\base.py", line 126, in _get_response
    "returned None instead." % (callback.__module__, view_name)
ValueError: The view firstAPI.views.addNewError didn't return an HttpResponse object. It returned None instead.
ERROR 2020-04-18 13:18:26,397 basehttp 17084 19660 "GET /addNewError/58 HTTP/1.1" 500 60482
